Workbook

Sheet Motivasi Berpretasi
A1: Correlations | Q1: Reliability Statistics
C2: MB1 | D2: MB2 | E2: MB3 | F2: MB4 | G2: MB5 | H2: MB6 | I2: MB7 | J2: MB | L2: Indikator | M2: Pearson | N2: p-value | O2: Keterangan | Q2: Cronbach's Alpha | R2: N of Items | T2: Cronbach's Alpha | U2: Keterangan
A3: MB1 | B3: Pearson Correlation | C3: 1 | D3: 0,438* | E3: 0,573** | F3: 0,451** | G3: 0.21947564 | H3: 0,365* | I3: 0,369* | J3: 0,661** | L3: {=INDIRECT("A" & (ROW(L1)*3))} -> MB1 | M3: {=INDIRECT("J" & (ROW(L1)*3))} -> 0,661** | N3: {=INDIRECT("J" & (ROW(L1)*3+1))} -> 3.8224994e-05 | O3: =IF(N3<0.05,"Valid","Tidak Valid") -> Valid | Q3: 0.82657767 | R3: 7 | T3: =Q3 -> 0.82657767 | U3: =IF(T3>0.6,"Reliabel","Tidak Reliabel") -> Reliabel
B4: Sig. (2-tailed) | D4: 0.012089296 | E4: 0.00061448988 | F4: 0.0096578021 | G4: 0.22745953 | H4: 0.039736026 | I4: 0.037432047 | J4: 3.8224994e-05 | L4: {=INDIRECT("A" & (ROW(L2)*3))} -> MB2 | M4: {=INDIRECT("J" & (ROW(L2)*3))} -> 0,715** | N4: {=INDIRECT("J" & (ROW(L2)*3+1))} -> 4.3223371e-06 | O4: =IF(N4<0.05,"Valid","Tidak Valid") -> Valid
B5: N | C5: 32 | D5: 32 | E5: 32 | F5: 32 | G5: 32 | H5: 32 | I5: 32 | J5: 32 | L5: {=INDIRECT("A" & (ROW(L3)*3))} -> MB3 | M5: {=INDIRECT("J" & (ROW(L3)*3))} -> 0,765** | N5: {=INDIRECT("J" & (ROW(L3)*3+1))} -> 3.3368586e-07 | O5: =IF(N5<0.05,"Valid","Tidak Valid") -> Valid
A6: MB2 | B6: Pearson Correlation | C6: 0,438* | D6: 1 | E6: 0,626** | F6: 0,480** | G6: 0.23364966 | H6: 0,494** | I6: 0,407* | J6: 0,715** | L6: {=INDIRECT("A" & (ROW(L4)*3))} -> MB4 | M6: {=INDIRECT("J" & (ROW(L4)*3))} -> 0,717** | N6: {=INDIRECT("J" & (ROW(L4)*3+1))} -> 3.9029486e-06 | O6: =IF(N6<0.05,"Valid","Tidak Valid") -> Valid
B7: Sig. (2-tailed) | C7: 0.012089296 | E7: 0.00012879754 | F7: 0.0054700424 | G7: 0.1980812 | H7: 0.0040933785 | I7: 0.020949838 | J7: 4.3223371e-06 | L7: {=INDIRECT("A" & (ROW(L5)*3))} -> MB5 | M7: {=INDIRECT("J" & (ROW(L5)*3))} -> 0,667** | N7: {=INDIRECT("J" & (ROW(L5)*3+1))} -> 3.0240109e-05 | O7: =IF(N7<0.05,"Valid","Tidak Valid") -> Valid
B8: N | C8: 32 | D8: 32 | E8: 32 | F8: 32 | G8: 32 | H8: 32 | I8: 32 | J8: 32 | L8: {=INDIRECT("A" & (ROW(L6)*3))} -> MB6 | M8: {=INDIRECT("J" & (ROW(L6)*3))} -> 0,688** | N8: {=INDIRECT("J" & (ROW(L6)*3+1))} -> 1.3656131e-05 | O8: =IF(N8<0.05,"Valid","Tidak Valid") -> Valid
A9: MB3 | B9: Pearson Correlation | C9: 0,573** | D9: 0,626** | E9: 1 | F9: 0,443* | G9: 0,444* | H9: 0.33545932 | I9: 0,487** | J9: 0,765** | L9: {=INDIRECT("A" & (ROW(L7)*3))} -> MB7 | M9: {=INDIRECT("J" & (ROW(L7)*3))} -> 0,742** | N9: {=INDIRECT("J" & (ROW(L7)*3+1))} -> 1.1784213e-06 | O9: =IF(N9<0.05,"Valid","Tidak Valid") -> Valid
B10: Sig. (2-tailed) | C10: 0.00061448988 | D10: 0.00012879754 | F10: 0.011156452 | G10: 0.010891179 | H10: 0.060525589 | I10: 0.0047088306 | J10: 3.3368586e-07
B11: N | C11: 32 | D11: 32 | E11: 32 | F11: 32 | G11: 32 | H11: 32 | I11: 32 | J11: 32
A12: MB4 | B12: Pearson Correlation | C12: 0,451** | D12: 0,480** | E12: 0,443* | F12: 1 | G12: 0.32303324 | H12: 0.33710891 | I12: 0,499** | J12: 0,717**
B13: Sig. (2-tailed) | C13: 0.0096578021 | D13: 0.0054700424 | E13: 0.011156452 | G13: 0.071334098 | H13: 0.05919331 | I13: 0.0036169494 | J13: 3.9029486e-06
B14: N | C14: 32 | D14: 32 | E14: 32 | F14: 32 | G14: 32 | H14: 32 | I14: 32 | J14: 32
A15: MB5 | B15: Pearson Correlation | C15: 0.21947564 | D15: 0.23364966 | E15: 0,444* | F15: 0.32303324 | G15: 1 | H15: 0,433* | I15: 0,466** | J15: 0,667**
B16: Sig. (2-tailed) | C16: 0.22745953 | D16: 0.1980812 | E16: 0.010891179 | F16: 0.071334098 | H16: 0.013294976 | I16: 0.0072349675 | J16: 3.0240109e-05
B17: N | C17: 32 | D17: 32 | E17: 32 | F17: 32 | G17: 32 | H17: 32 | I17: 32 | J17: 32
A18: MB6 | B18: Pearson Correlation | C18: 0,365* | D18: 0,494** | E18: 0.33545932 | F18: 0.33710891 | G18: 0,433* | H18: 1 | I18: 0,405* | J18: 0,688**
B19: Sig. (2-tailed) | C19: 0.039736026 | D19: 0.0040933785 | E19: 0.060525589 | F19: 0.05919331 | G19: 0.013294976 | I19: 0.021488474 | J19: 1.3656131e-05
B20: N | C20: 32 | D20: 32 | E20: 32 | F20: 32 | G20: 32 | H20: 32 | I20: 32 | J20: 32
A21: MB7 | B21: Pearson Correlation | C21: 0,369* | D21: 0,407* | E21: 0,487** | F21: 0,499** | G21: 0,466** | H21: 0,405* | I21: 1 | J21: 0,742**
B22: Sig. (2-tailed) | C22: 0.037432047 | D22: 0.020949838 | E22: 0.0047088306 | F22: 0.0036169494 | G22: 0.0072349675 | H22: 0.021488474 | J22: 1.1784213e-06
B23: N | C23: 32 | D23: 32 | E23: 32 | F23: 32 | G23: 32 | H23: 32 | I23: 32 | J23: 32
A24: MB | B24: Pearson Correlation | C24: 0,661** | D24: 0,715** | E24: 0,765** | F24: 0,717** | G24: 0,667** | H24: 0,688** | I24: 0,742** | J24: 1
B25: Sig. (2-tailed) | C25: 3.8224994e-05 | D25: 4.3223371e-06 | E25: 3.3368586e-07 | F25: 3.9029486e-06 | G25: 3.0240109e-05 | H25: 1.3656131e-05 | I25: 1.1784213e-06
B26: N | C26: 32 | D26: 32 | E26: 32 | F26: 32 | G26: 32 | H26: 32 | I26: 32 | J26: 32
A27: *. Correlation is significant at the 0.05 level (2-tailed).
A28: **. Correlation is significant at the 0.01 level (2-tailed).

Sheet Komitmen Pegawai
A1: Correlations | U1: Reliability Statistics
C2: KP1 | D2: KP2 | E2: KP3 | F2: KP4 | G2: KP5 | H2: KP6 | I2: KP7 | J2: KP8 | K2: KP9 | L2: KP10 | M2: KP11 | N2: KP | P2: Indikator | Q2: Pearson | R2: p-value | S2: Keterangan | U2: Cronbach's Alpha | V2: N of Items | X2: Cronbach's Alpha | Y2: Keterangan
A3: KP1 | B3: Pearson Correlation | C3: 1 | D3: 0,758** | E3: 0,504** | F3: 0,402* | G3: 0,581** | H3: 0,606** | I3: -0,551** | J3: -0,411* | K3: 0.059855027 | L3: 0.34880076 | M3: 0,525** | N3: 0,541** | P3: {=INDIRECT("A" & (ROW(P1)*3))} -> KP1 | Q3: {=INDIRECT("N" & (ROW(P1)*3))} -> 0,541** | R3: {=INDIRECT("N" & (ROW(N1)*3+1))} -> 0.0013998429 | S3: =IF(R3<0.05,"Valid","Tidak Valid") -> Valid | U3: 0.55321195 | V3: 11 | X3: =U3 -> 0.55321195 | Y3: =IF(X3>0.6,"Reliabel","Tidak Reliabel") -> Tidak Reliabel
B4: Sig. (2-tailed) | D4: 5.0903429e-07 | E4: 0.0032778706 | F4: 0.022534592 | G4: 0.0004930973 | H4: 0.0002351741 | I4: 0.0010947737 | J4: 0.019599291 | K4: 0.74486933 | L4: 0.050400008 | M4: 0.0020180195 | N4: 0.0013998429 | P4: {=INDIRECT("A" & (ROW(P2)*3))} -> KP2 | Q4: {=INDIRECT("N" & (ROW(P2)*3))} -> 0,685** | R4: {=INDIRECT("N" & (ROW(N2)*3+1))} -> 1.5511887e-05 | S4: =IF(R4<0.05,"Valid","Tidak Valid") -> Valid
B5: N | C5: 32 | D5: 32 | E5: 32 | F5: 32 | G5: 32 | H5: 32 | I5: 32 | J5: 32 | K5: 32 | L5: 32 | M5: 32 | N5: 32 | P5: {=INDIRECT("A" & (ROW(P3)*3))} -> KP3 | Q5: {=INDIRECT("N" & (ROW(P3)*3))} -> 0,797** | R5: {=INDIRECT("N" & (ROW(N3)*3+1))} -> 4.8090071e-08 | S5: =IF(R5<0.05,"Valid","Tidak Valid") -> Valid
A6: KP2 | B6: Pearson Correlation | C6: .758** | D6: 1 | E6: 0,688** | F6: 0,491** | G6: 0,569** | H6: 0,812** | I6: -0,384* | J6: -0.29481739 | K6: 0 | L6: 0,414* | M6: 0,431* | N6: 0,685** | P6: {=INDIRECT("A" & (ROW(P4)*3))} -> KP4 | Q6: {=INDIRECT("N" & (ROW(P4)*3))} -> 0,726** | R6: {=INDIRECT("N" & (ROW(N4)*3+1))} -> 2.5391012e-06 | S6: =IF(R6<0.05,"Valid","Tidak Valid") -> Valid
B7: Sig. (2-tailed) | C7: 5.0903429e-07 | E7: 1.3387422e-05 | F7: 0.0042917472 | G7: 0.00067260112 | H7: 1.7325898e-08 | I7: 0.029965525 | J7: 0.10141626 | K7: 1 | L7: 0.018473118 | M7: 0.013904803 | N7: 1.5511887e-05 | P7: {=INDIRECT("A" & (ROW(P5)*3))} -> KP5 | Q7: {=INDIRECT("N" & (ROW(P5)*3))} -> 0,629** | R7: {=INDIRECT("N" & (ROW(N5)*3+1))} -> 0.00011687786 | S7: =IF(R7<0.05,"Valid","Tidak Valid") -> Valid
B8: N | C8: 32 | D8: 32 | E8: 32 | F8: 32 | G8: 32 | H8: 32 | I8: 32 | J8: 32 | K8: 32 | L8: 32 | M8: 32 | N8: 32 | P8: {=INDIRECT("A" & (ROW(P6)*3))} -> KP6 | Q8: {=INDIRECT("N" & (ROW(P6)*3))} -> 0,785** | R8: {=INDIRECT("N" & (ROW(N6)*3+1))} -> 1.0484727e-07 | S8: =IF(R8<0.05,"Valid","Tidak Valid") -> Valid
A9: KP3 | B9: Pearson Correlation | C9: .504** | D9: 0,688** | E9: 1 | F9: 0,630** | G9: 0,573** | H9: 0,750** | I9: -0.33487441 | J9: -0.075592895 | K9: 0.20044593 | L9: 0,524** | M9: 0.34752402 | N9: 0,797** | P9: {=INDIRECT("A" & (ROW(P7)*3))} -> KP7 | Q9: {=INDIRECT("N" & (ROW(P7)*3))} -> -0.17435189 | R9: {=INDIRECT("N" & (ROW(N7)*3+1))} -> 0.33989129 | S9: =IF(R9<0.05,"Valid","Tidak Valid") -> Tidak Valid
B10: Sig. (2-tailed) | C10: 0.0032778706 | D10: 1.3387422e-05 | F10: 0.00011178563 | G10: 0.00061448988 | H10: 7.5578954e-07 | I10: 0.06100361 | J10: 0.68093026 | K10: 0.27133601 | L10: 0.0020827673 | M10: 0.05130643 | N10: 4.8090071e-08 | P10: {=INDIRECT("A" & (ROW(P8)*3))} -> KP8 | Q10: {=INDIRECT("N" & (ROW(P8)*3))} -> 0.035026753 | R10: {=INDIRECT("N" & (ROW(N8)*3+1))} -> 0.84906138 | S10: =IF(R10<0.05,"Valid","Tidak Valid") -> Tidak Valid
B11: N | C11: 32 | D11: 32 | E11: 32 | F11: 32 | G11: 32 | H11: 32 | I11: 32 | J11: 32 | K11: 32 | L11: 32 | M11: 32 | N11: 32 | P11: {=INDIRECT("A" & (ROW(P9)*3))} -> KP9 | Q11: {=INDIRECT("N" & (ROW(P9)*3))} -> 0,456** | R11: {=INDIRECT("N" & (ROW(N9)*3+1))} -> 0.0087618619 | S11: =IF(R11<0.05,"Valid","Tidak Valid") -> Valid
A12: KP4 | B12: Pearson Correlation | C12: .402* | D12: 0,491** | E12: 0,630** | F12: 1 | G12: 0,553** | H12: 0,581** | I12: -0.26464768 | J12: -0.066666667 | K12: 0.13468701 | L12: 0,506** | M12: 0,429* | N12: 0,726** | P12: {=INDIRECT("A" & (ROW(P10)*3))} -> KP10 | Q12: {=INDIRECT("N" & (ROW(P10)*3))} -> 0,644** | R12: {=INDIRECT("N" & (ROW(N10)*3+1))} -> 6.9215071e-05 | S12: =IF(R12<0.05,"Valid","Tidak Valid") -> Valid
B13: Sig. (2-tailed) | C13: 0.022534592 | D13: 0.0042917472 | E13: 0.00011178563 | G13: 0.0010254006 | H13: 0.00049136576 | I13: 0.14326074 | J13: 0.71696114 | K13: 0.4623696 | L13: 0.0031209436 | M13: 0.014263951 | N13: 2.5391012e-06 | P13: {=INDIRECT("A" & (ROW(P11)*3))} -> KP11 | Q13: {=INDIRECT("N" & (ROW(P11)*3))} -> 0,455** | R13: {=INDIRECT("N" & (ROW(N11)*3+1))} -> 0.0089262249 | S13: =IF(R13<0.05,"Valid","Tidak Valid") -> Valid
B14: N | C14: 32 | D14: 32 | E14: 32 | F14: 32 | G14: 32 | H14: 32 | I14: 32 | J14: 32 | K14: 32 | L14: 32 | M14: 32 | N14: 32
A15: KP5 | B15: Pearson Correlation | C15: .581** | D15: 0,569** | E15: 0,573** | F15: 0,553** | G15: 1 | H15: 0,662** | I15: -0,416* | J15: -0,447* | K15: 0.068021702 | L15: 0,470** | M15: 0,615** | N15: 0,629**
B16: Sig. (2-tailed) | C16: 0.0004930973 | D16: 0.00067260112 | E16: 0.00061448988 | F16: 0.0010254006 | H16: 3.7224484e-05 | I16: 0.017739531 | J16: 0.010260118 | K16: 0.71145059 | L16: 0.0065786577 | M16: 0.00018154441 | N16: 0.00011687786
B17: N | C17: 32 | D17: 32 | E17: 32 | F17: 32 | G17: 32 | H17: 32 | I17: 32 | J17: 32 | K17: 32 | L17: 32 | M17: 32 | N17: 32
A18: KP6 | B18: Pearson Correlation | C18: .606** | D18: 0,812** | E18: 0,750** | F18: 0,581** | G18: 0,662** | H18: 1 | I18: -0.21214999 | J18: -0.21881904 | K18: 0 | L18: 0,456** | M18: 0,455** | N18: 0,785**
B19: Sig. (2-tailed) | C19: 0.0002351741 | D19: 1.7325898e-08 | E19: 7.5578954e-07 | F19: 0.00049136576 | G19: 3.7224484e-05 | I19: 0.24374299 | J19: 0.22888822 | K19: 1 | L19: 0.0087706857 | M19: 0.0089587513 | N19: 1.0484727e-07
B20: N | C20: 32 | D20: 32 | E20: 32 | F20: 32 | G20: 32 | H20: 32 | I20: 32 | J20: 32 | K20: 32 | L20: 32 | M20: 32 | N20: 32
A21: KP7 | B21: Pearson Correlation | C21: -.551** | D21: -0,384* | E21: -0.33487441 | F21: -0.26464768 | G21: -0,416* | H21: -0.21214999 | I21: 1 | J21: 0,619** | K21: -0.097635219 | L21: -0,622** | M21: -0,497** | N21: -0.17435189
B22: Sig. (2-tailed) | C22: 0.0010947737 | D22: 0.029965525 | E22: 0.06100361 | F22: 0.14326074 | G22: 0.017739531 | H22: 0.24374299 | J22: 0.00015859819 | K22: 0.59499817 | L22: 0.00014380754 | M22: 0.0037866739 | N22: 0.33989129
B23: N | C23: 32 | D23: 32 | E23: 32 | F23: 32 | G23: 32 | H23: 32 | I23: 32 | J23: 32 | K23: 32 | L23: 32 | M23: 32 | N23: 32
A24: KP8 | B24: Pearson Correlation | C24: -.411* | D24: -0.29481739 | E24: -0.075592895 | F24: -0.066666667 | G24: -0,447* | H24: -0.21881904 | I24: 0,619** | J24: 1 | K24: 0.040406102 | L24: -0.33889151 | M24: -0,468** | N24: 0.035026753
B25: Sig. (2-tailed) | C25: 0.019599291 | D25: 0.10141626 | E25: 0.68093026 | F25: 0.71696114 | G25: 0.010260118 | H25: 0.22888822 | I25: 0.00015859819 | K25: 0.82620842 | L25: 0.057779673 | M25: 0.0069625873 | N25: 0.84906138
B26: N | C26: 32 | D26: 32 | E26: 32 | F26: 32 | G26: 32 | H26: 32 | I26: 32 | J26: 32 | K26: 32 | L26: 32 | M26: 32 | N26: 32
A27: KP9 | B27: Pearson Correlation | C27: 0.059855027 | D27: 0 | E27: 0.20044593 | F27: 0.13468701 | G27: 0.068021702 | H27: 0 | I27: -0.097635219 | J27: 0.040406102 | K27: 1 | L27: 0,405* | M27: 0 | N27: 0,456**
B28: Sig. (2-tailed) | C28: 0.74486933 | D28: 1 | E28: 0.27133601 | F28: 0.4623696 | G28: 0.71145059 | H28: 1 | I28: 0.59499817 | J28: 0.82620842 | L28: 0.021633201 | M28: 1 | N28: 0.0087618619
B29: N | C29: 32 | D29: 32 | E29: 32 | F29: 32 | G29: 32 | H29: 32 | I29: 32 | J29: 32 | K29: 32 | L29: 32 | M29: 32 | N29: 32
A30: KP10 | B30: Pearson Correlation | C30: 0.34880076 | D30: 0,414* | E30: 0,524** | F30: 0,506** | G30: 0,470** | H30: 0,456** | I30: -0,622** | J30: -0.33889151 | K30: 0,405* | L30: 1 | M30: 0,465** | N30: 0,644**
B31: Sig. (2-tailed) | C31: 0.050400008 | D31: 0.018473118 | E31: 0.0020827673 | F31: 0.0031209436 | G31: 0.0065786577 | H31: 0.0087706857 | I31: 0.00014380754 | J31: 0.057779673 | K31: 0.021633201 | M31: 0.0072750326 | N31: 6.9215071e-05
B32: N | C32: 32 | D32: 32 | E32: 32 | F32: 32 | G32: 32 | H32: 32 | I32: 32 | J32: 32 | K32: 32 | L32: 32 | M32: 32 | N32: 32
A33: KP11 | B33: Pearson Correlation | C33: .525** | D33: 0,431* | E33: 0.34752402 | F33: 0,429* | G33: 0,615** | H33: 0,455** | I33: -0,497** | J33: -0,468** | K33: 0 | L33: 0,465** | M33: 1 | N33: 0,455**
B34: Sig. (2-tailed) | C34: 0.0020180195 | D34: 0.013904803 | E34: 0.05130643 | F34: 0.014263951 | G34: 0.00018154441 | H34: 0.0089587513 | I34: 0.0037866739 | J34: 0.0069625873 | K34: 1 | L34: 0.0072750326 | N34: 0.0089262249
B35: N | C35: 32 | D35: 32 | E35: 32 | F35: 32 | G35: 32 | H35: 32 | I35: 32 | J35: 32 | K35: 32 | L35: 32 | M35: 32 | N35: 32
A36: KP | B36: Pearson Correlation | C36: .541** | D36: 0,685** | E36: 0,797** | F36: 0,726** | G36: 0,629** | H36: 0,785** | I36: -0.17435189 | J36: 0.035026753 | K36: 0,456** | L36: 0,644** | M36: 0,455** | N36: 1
B37: Sig. (2-tailed) | C37: 0.0013998429 | D37: 1.5511887e-05 | E37: 4.8090071e-08 | F37: 2.5391012e-06 | G37: 0.00011687786 | H37: 1.0484727e-07 | I37: 0.33989129 | J37: 0.84906138 | K37: 0.0087618619 | L37: 6.9215071e-05 | M37: 0.0089262249
B38: N | C38: 32 | D38: 32 | E38: 32 | F38: 32 | G38: 32 | H38: 32 | I38: 32 | J38: 32 | K38: 32 | L38: 32 | M38: 32 | N38: 32
A39: **. Correlation is significant at the 0.01 level (2-tailed).
A40: *. Correlation is significant at the 0.05 level (2-tailed).

Sheet Budaya Organisasi
A1: Correlations | AC1: Reliability Statistics
C2: BO1 | D2: BO2 | E2: BO3 | F2: BO4 | G2: BO5 | H2: BO6 | I2: BO7 | J2: BO8 | K2: BO9 | L2: BO10 | M2: BO11 | N2: BO12 | O2: BO13 | P2: BO14 | Q2: BO15 | R2: BO16 | S2: BO17 | T2: BO18 | U2: BO19 | V2: BO | X2: Indikator | Y2: Pearson | Z2: p-value | AA2: Keterangan | AC2: Cronbach's Alpha | AD2: N of Items | AF2: Cronbach's Alpha | AG2: Keterangan
A3: BO1 | B3: Pearson Correlation | C3: 1 | D3: 0,741** | E3: 0,508** | F3: 0,620** | G3: 0,376* | H3: 0,462** | I3: 0,403* | J3: 0.27373458 | K3: 0.28111657 | L3: 0,434* | M3: 0.20064309 | N3: 0.2997346 | O3: 0.19781414 | P3: 0.30330926 | Q3: 0.20124024 | R3: 0.17748863 | S3: 0.023200115 | T3: 0.040987737 | U3: 0.27929019 | V3: 0,500** | X3: {=INDIRECT("A" & (ROW(X1)*3))} -> BO1 | Y3: {=INDIRECT("V" & (ROW(X1)*3))} -> 0,500** | Z3: {=INDIRECT("V" & (ROW(V1)*3+1))} -> 0.0035480629 | AA3: =IF(Z3<0.05,"Valid","Tidak Valid") -> Valid | AC3: 0.9372805 | AD3: 19 | AF3: =AC3 -> 0.9372805 | AG3: =IF(AF3>0.6,"Reliabel","Tidak Reliabel") -> Reliabel
B4: Sig. (2-tailed) | D4: 1.2437692e-06 | E4: 0.0029671339 | F4: 0.00015191451 | G4: 0.033914111 | H4: 0.0078338025 | I4: 0.022059328 | J4: 0.12952108 | K4: 0.11909442 | L4: 0.012964087 | M4: 0.27085505 | N4: 0.095580982 | O4: 0.27780937 | P4: 0.091501659 | Q4: 0.26940168 | R4: 0.33113703 | S4: 0.89970427 | T4: 0.82374547 | U4: 0.12161394 | V4: 0.0035480629 | X4: {=INDIRECT("A" & (ROW(X2)*3))} -> BO2 | Y4: {=INDIRECT("V" & (ROW(X2)*3))} -> 0,371* | Z4: {=INDIRECT("V" & (ROW(V2)*3+1))} -> 0.036744703 | AA4: =IF(Z4<0.05,"Valid","Tidak Valid") -> Valid
B5: N | C5: 32 | D5: 32 | E5: 32 | F5: 32 | G5: 32 | H5: 32 | I5: 32 | J5: 32 | K5: 32 | L5: 32 | M5: 32 | N5: 32 | O5: 32 | P5: 32 | Q5: 32 | R5: 32 | S5: 32 | T5: 32 | U5: 32 | V5: 32 | X5: {=INDIRECT("A" & (ROW(X3)*3))} -> BO3 | Y5: {=INDIRECT("V" & (ROW(X3)*3))} -> 0,441* | Z5: {=INDIRECT("V" & (ROW(V3)*3+1))} -> 0.011500942 | AA5: =IF(Z5<0.05,"Valid","Tidak Valid") -> Valid
A6: BO2 | B6: Pearson Correlation | C6: 0,741** | D6: 1 | E6: 0,699** | F6: 0,541** | G6: 0.16502408 | H6: 0,430* | I6: 0,357* | J6: 0.18744807 | K6: 0.14987266 | L6: 0,443* | M6: 0.10183502 | N6: 0.28851905 | O6: 0.11952286 | P6: 0.20505857 | Q6: -0.04377347 | R6: -0.076044199 | S6: -0.036446609 | T6: -0.17533994 | U6: 0.052159756 | V6: 0,371* | X6: {=INDIRECT("A" & (ROW(X4)*3))} -> BO4 | Y6: {=INDIRECT("V" & (ROW(X4)*3))} -> 0,610** | Z6: {=INDIRECT("V" & (ROW(V4)*3+1))} -> 0.00021101342 | AA6: =IF(Z6<0.05,"Valid","Tidak Valid") -> Valid
B7: Sig. (2-tailed) | C7: 1.2437692e-06 | E7: 8.6896475e-06 | F7: 0.0014020944 | G7: 0.36674538 | H7: 0.013965382 | I7: 0.044992241 | J7: 0.30426942 | K7: 0.41294827 | L7: 0.011149119 | M7: 0.57917398 | N7: 0.10927888 | O7: 0.51468166 | P7: 0.26022878 | Q7: 0.81197246 | R7: 0.67912599 | S7: 0.84301695 | T7: 0.33711871 | U7: 0.77678296 | V7: 0.036744703 | X7: {=INDIRECT("A" & (ROW(X5)*3))} -> BO5 | Y7: {=INDIRECT("V" & (ROW(X5)*3))} -> 0,737** | Z7: {=INDIRECT("V" & (ROW(V5)*3+1))} -> 1.4958628e-06 | AA7: =IF(Z7<0.05,"Valid","Tidak Valid") -> Valid
B8: N | C8: 32 | D8: 32 | E8: 32 | F8: 32 | G8: 32 | H8: 32 | I8: 32 | J8: 32 | K8: 32 | L8: 32 | M8: 32 | N8: 32 | O8: 32 | P8: 32 | Q8: 32 | R8: 32 | S8: 32 | T8: 32 | U8: 32 | V8: 32 | X8: {=INDIRECT("A" & (ROW(X6)*3))} -> BO6 | Y8: {=INDIRECT("V" & (ROW(X6)*3))} -> 0,830** | Z8: {=INDIRECT("V" & (ROW(V6)*3+1))} -> 4.1069043e-09 | AA8: =IF(Z8<0.05,"Valid","Tidak Valid") -> Valid
A9: BO3 | B9: Pearson Correlation | C9: 0,508** | D9: 0,699** | E9: 1 | F9: 0,678** | G9: 0,361* | H9: 0,394* | I9: 0,426* | J9: 0.17369614 | K9: 0.13041251 | L9: 0,430* | M9: 0.12004128 | N9: 0.25015697 | O9: 0.19724795 | P9: 0,359* | Q9: 0.0985079 | R9: -0.039491541 | S9: 0.014721452 | T9: 0.073566756 | U9: 0.25087186 | V9: 0,441* | X9: {=INDIRECT("A" & (ROW(X7)*3))} -> BO7 | Y9: {=INDIRECT("V" & (ROW(X7)*3))} -> 0,848** | Z9: {=INDIRECT("V" & (ROW(V7)*3+1))} -> 9.2674778e-10 | AA9: =IF(Z9<0.05,"Valid","Tidak Valid") -> Valid
B10: Sig. (2-tailed) | C10: 0.0029671339 | D10: 8.6896475e-06 | F10: 2.0244861e-05 | G10: 0.042608283 | H10: 0.025462474 | I10: 0.015152604 | J10: 0.34173903 | K10: 0.47682362 | L10: 0.013972348 | M10: 0.51284641 | N10: 0.16731866 | O10: 0.27921496 | P10: 0.043660053 | Q10: 0.59169466 | R10: 0.83008441 | S10: 0.93626268 | T10: 0.68905177 | U10: 0.16606825 | V10: 0.011500942 | X10: {=INDIRECT("A" & (ROW(X8)*3))} -> BO8 | Y10: {=INDIRECT("V" & (ROW(X8)*3))} -> 0,817** | Z10: {=INDIRECT("V" & (ROW(V8)*3+1))} -> 1.1804168e-08 | AA10: =IF(Z10<0.05,"Valid","Tidak Valid") -> Valid
B11: N | C11: 32 | D11: 32 | E11: 32 | F11: 32 | G11: 32 | H11: 32 | I11: 32 | J11: 32 | K11: 32 | L11: 32 | M11: 32 | N11: 32 | O11: 32 | P11: 32 | Q11: 32 | R11: 32 | S11: 32 | T11: 32 | U11: 32 | V11: 32 | X11: {=INDIRECT("A" & (ROW(X9)*3))} -> BO9 | Y11: {=INDIRECT("V" & (ROW(X9)*3))} -> 0,742** | Z11: {=INDIRECT("V" & (ROW(V9)*3+1))} -> 1.1676842e-06 | AA11: =IF(Z11<0.05,"Valid","Tidak Valid") -> Valid
A12: BO4 | B12: Pearson Correlation | C12: 0,620** | D12: 0,541** | E12: 0,678** | F12: 1 | G12: 0,520** | H12: 0,495** | I12: 0,465** | J12: 0,419* | K12: 0,426* | L12: 0,466** | M12: 0,412* | N12: 0,360* | O12: 0.34664606 | P12: 0.33450486 | Q12: 0.20755965 | R12: 0.21408419 | S12: 0.16455788 | T12: 0.26883519 | U12: 0,354* | V12: 0,610** | X12: {=INDIRECT("A" & (ROW(X10)*3))} -> BO10 | Y12: {=INDIRECT("V" & (ROW(X10)*3))} -> 0,778** | Z12: {=INDIRECT("V" & (ROW(V10)*3+1))} -> 1.5718069e-07 | AA12: =IF(Z12<0.05,"Valid","Tidak Valid") -> Valid
B13: Sig. (2-tailed) | C13: 0.00015191451 | D13: 0.0014020944 | E13: 2.0244861e-05 | G13: 0.0022725336 | H13: 0.0039554766 | I13: 0.0073969246 | J13: 0.017055469 | K13: 0.014953675 | L13: 0.0072083685 | M13: 0.019166181 | N13: 0.043198649 | O13: 0.05193722 | P13: 0.061307154 | Q13: 0.25433287 | R13: 0.23937014 | S13: 0.3681196 | T13: 0.13680302 | U13: 0.046955658 | V13: 0.00021101342 | X13: {=INDIRECT("A" & (ROW(X11)*3))} -> BO11 | Y13: {=INDIRECT("V" & (ROW(X11)*3))} -> 0,649** | Z13: {=INDIRECT("V" & (ROW(V11)*3+1))} -> 5.9432711e-05 | AA13: =IF(Z13<0.05,"Valid","Tidak Valid") -> Valid
B14: N | C14: 32 | D14: 32 | E14: 32 | F14: 32 | G14: 32 | H14: 32 | I14: 32 | J14: 32 | K14: 32 | L14: 32 | M14: 32 | N14: 32 | O14: 32 | P14: 32 | Q14: 32 | R14: 32 | S14: 32 | T14: 32 | U14: 32 | V14: 32 | X14: {=INDIRECT("A" & (ROW(X12)*3))} -> BO12 | Y14: {=INDIRECT("V" & (ROW(X12)*3))} -> 0,646** | Z14: {=INDIRECT("V" & (ROW(V12)*3+1))} -> 6.6010221e-05 | AA14: =IF(Z14<0.05,"Valid","Tidak Valid") -> Valid
A15: BO5 | B15: Pearson Correlation | C15: 0,376* | D15: 0.16502408 | E15: 0,361* | F15: 0,520** | G15: 1 | H15: 0,600** | I15: 0,624** | J15: 0,678** | K15: 0,549** | L15: 0,496** | M15: 0.27399831 | N15: 0.28699289 | O15: 0,570** | P15: 0,556** | Q15: 0,473** | R15: 0,433* | S15: 0,517** | T15: 0,496** | U15: 0,620** | V15: 0,737** | X15: {=INDIRECT("A" & (ROW(X13)*3))} -> BO13 | Y15: {=INDIRECT("V" & (ROW(X13)*3))} -> 0,694** | Z15: {=INDIRECT("V" & (ROW(V13)*3+1))} -> 1.0560624e-05 | AA15: =IF(Z15<0.05,"Valid","Tidak Valid") -> Valid
B16: Sig. (2-tailed) | C16: 0.033914111 | D16: 0.36674538 | E16: 0.042608283 | F16: 0.0022725336 | H16: 0.00028110599 | I16: 0.00013416128 | J16: 1.9802171e-05 | K16: 0.0011242776 | L16: 0.0038648915 | M16: 0.12913736 | N16: 0.11125111 | O16: 0.00065503056 | P16: 0.00095307268 | Q16: 0.0062972841 | R16: 0.013227325 | S16: 0.0024205096 | T16: 0.0038648915 | U16: 0.00015265705 | V16: 1.4958628e-06 | X16: {=INDIRECT("A" & (ROW(X14)*3))} -> BO14 | Y16: {=INDIRECT("V" & (ROW(X14)*3))} -> 0,682** | Z16: {=INDIRECT("V" & (ROW(V14)*3+1))} -> 1.7289518e-05 | AA16: =IF(Z16<0.05,"Valid","Tidak Valid") -> Valid
B17: N | C17: 32 | D17: 32 | E17: 32 | F17: 32 | G17: 32 | H17: 32 | I17: 32 | J17: 32 | K17: 32 | L17: 32 | M17: 32 | N17: 32 | O17: 32 | P17: 32 | Q17: 32 | R17: 32 | S17: 32 | T17: 32 | U17: 32 | V17: 32 | X17: {=INDIRECT("A" & (ROW(X15)*3))} -> BO15 | Y17: {=INDIRECT("V" & (ROW(X15)*3))} -> 0,728** | Z17: {=INDIRECT("V" & (ROW(V15)*3+1))} -> 2.3051543e-06 | AA17: =IF(Z17<0.05,"Valid","Tidak Valid") -> Valid
A18: BO6 | B18: Pearson Correlation | C18: 0,462** | D18: 0,430* | E18: 0,394* | F18: 0,495** | G18: 0,600** | H18: 1 | I18: 0,685** | J18: 0,738** | K18: 0,652** | L18: 0,721** | M18: 0,548** | N18: 0,596** | O18: 0,550** | P18: 0,572** | Q18: 0,464** | R18: 0,489** | S18: 0,586** | T18: 0,423* | U18: 0,385* | V18: 0,830** | X18: {=INDIRECT("A" & (ROW(X16)*3))} -> BO16 | Y18: {=INDIRECT("V" & (ROW(X16)*3))} -> 0,740** | Z18: {=INDIRECT("V" & (ROW(V16)*3+1))} -> 1.2709801e-06 | AA18: =IF(Z18<0.05,"Valid","Tidak Valid") -> Valid
B19: Sig. (2-tailed) | C19: 0.0078338025 | D19: 0.013965382 | E19: 0.025462474 | F19: 0.0039554766 | G19: 0.00028110599 | I19: 1.5152388e-05 | J19: 1.4312139e-06 | K19: 5.2711853e-05 | L19: 3.2319303e-06 | M19: 0.0011753423 | N19: 0.00032229234 | O19: 0.0011100465 | P19: 0.00062749464 | Q19: 0.0074874506 | R19: 0.0044717529 | S19: 0.00042006531 | T19: 0.015944648 | U19: 0.029536192 | V19: 4.1069043e-09 | X19: {=INDIRECT("A" & (ROW(X17)*3))} -> BO17 | Y19: {=INDIRECT("V" & (ROW(X17)*3))} -> 0,738** | Z19: {=INDIRECT("V" & (ROW(V17)*3+1))} -> 1.4476327e-06 | AA19: =IF(Z19<0.05,"Valid","Tidak Valid") -> Valid
B20: N | C20: 32 | D20: 32 | E20: 32 | F20: 32 | G20: 32 | H20: 32 | I20: 32 | J20: 32 | K20: 32 | L20: 32 | M20: 32 | N20: 32 | O20: 32 | P20: 32 | Q20: 32 | R20: 32 | S20: 32 | T20: 32 | U20: 32 | V20: 32 | X20: {=INDIRECT("A" & (ROW(X18)*3))} -> BO18 | Y20: {=INDIRECT("V" & (ROW(X18)*3))} -> 0,674** | Z20: {=INDIRECT("V" & (ROW(V18)*3+1))} -> 2.3641012e-05 | AA20: =IF(Z20<0.05,"Valid","Tidak Valid") -> Valid
A21: BO7 | B21: Pearson Correlation | C21: 0,403* | D21: 0,357* | E21: 0,426* | F21: 0,465** | G21: 0,624** | H21: 0,685** | I21: 1 | J21: 0,576** | K21: 0,558** | L21: 0,703** | M21: 0,432* | N21: 0,549** | O21: 0,514** | P21: 0,654** | Q21: 0,654** | R21: 0,581** | S21: 0,600** | T21: 0,605** | U21: 0,587** | V21: 0,848** | X21: {=INDIRECT("A" & (ROW(X19)*3))} -> BO19 | Y21: {=INDIRECT("V" & (ROW(X19)*3))} -> 0,745** | Z21: {=INDIRECT("V" & (ROW(V19)*3+1))} -> 1.0085767e-06 | AA21: =IF(Z21<0.05,"Valid","Tidak Valid") -> Valid
B22: Sig. (2-tailed) | C22: 0.022059328 | D22: 0.044992241 | E22: 0.015152604 | F22: 0.0073969246 | G22: 0.00013416128 | H22: 1.5152388e-05 | J22: 0.00056638242 | K22: 0.00089470852 | L22: 7.311953e-06 | M22: 0.013577236 | N22: 0.0011525393 | O22: 0.0026261137 | P22: 4.9037885e-05 | Q22: 4.8784397e-05 | R22: 0.000491061 | S22: 0.00028512655 | T22: 0.00024142211 | U22: 0.00040917972 | V22: 9.2674778e-10
B23: N | C23: 32 | D23: 32 | E23: 32 | F23: 32 | G23: 32 | H23: 32 | I23: 32 | J23: 32 | K23: 32 | L23: 32 | M23: 32 | N23: 32 | O23: 32 | P23: 32 | Q23: 32 | R23: 32 | S23: 32 | T23: 32 | U23: 32 | V23: 32
A24: BO8 | B24: Pearson Correlation | C24: 0.27373458 | D24: 0.18744807 | E24: 0.17369614 | F24: 0,419* | G24: 0,678** | H24: 0,738** | I24: 0,576** | J24: 1 | K24: 0,683** | L24: 0,614** | M24: 0,533** | N24: 0,542** | O24: 0,738** | P24: 0,522** | Q24: 0,535** | R24: 0,553** | S24: 0,633** | T24: 0,476** | U24: 0,610** | V24: 0,817**
B25: Sig. (2-tailed) | C25: 0.12952108 | D25: 0.30426942 | E25: 0.34173903 | F25: 0.017055469 | G25: 1.9802171e-05 | H25: 1.4312139e-06 | I25: 0.00056638242 | K25: 1.6852135e-05 | L25: 0.00018800962 | M25: 0.001670024 | N25: 0.0013455335 | O25: 1.4312139e-06 | P25: 0.0021895353 | Q25: 0.0016076335 | R25: 0.0010267772 | S25: 0.00010125231 | T25: 0.0058953528 | U25: 0.00021121815 | V25: 1.1804168e-08
B26: N | C26: 32 | D26: 32 | E26: 32 | F26: 32 | G26: 32 | H26: 32 | I26: 32 | J26: 32 | K26: 32 | L26: 32 | M26: 32 | N26: 32 | O26: 32 | P26: 32 | Q26: 32 | R26: 32 | S26: 32 | T26: 32 | U26: 32 | V26: 32
A27: BO9 | B27: Pearson Correlation | C27: 0.28111657 | D27: 0.14987266 | E27: 0.13041251 | F27: 0,426* | G27: 0,549** | H27: 0,652** | I27: 0,558** | J27: 0,683** | K27: 1 | L27: 0,683** | M27: 0,382* | N27: 0,704** | O27: 0,426* | P27: 0.28372048 | Q27: 0,438* | R27: 0,669** | S27: 0,556** | T27: 0,483** | U27: 0,512** | V27: 0,742**
B28: Sig. (2-tailed) | C28: 0.11909442 | D28: 0.41294827 | E28: 0.47682362 | F28: 0.014953675 | G28: 0.0011242776 | H28: 5.2711853e-05 | I28: 0.00089470852 | J28: 1.6852135e-05 | L28: 1.6654919e-05 | M28: 0.031176742 | N28: 7.0344919e-06 | O28: 0.01496785 | P28: 0.11556967 | Q28: 0.012211418 | R28: 2.84816e-05 | S28: 0.00095547359 | T28: 0.0050812822 | U28: 0.0027515221 | V28: 1.1676842e-06
B29: N | C29: 32 | D29: 32 | E29: 32 | F29: 32 | G29: 32 | H29: 32 | I29: 32 | J29: 32 | K29: 32 | L29: 32 | M29: 32 | N29: 32 | O29: 32 | P29: 32 | Q29: 32 | R29: 32 | S29: 32 | T29: 32 | U29: 32 | V29: 32
A30: BO10 | B30: Pearson Correlation | C30: 0,434* | D30: 0,443* | E30: 0,430* | F30: 0,466** | G30: 0,496** | H30: 0,721** | I30: 0,703** | J30: 0,614** | K30: 0,683** | L30: 1 | M30: 0,462** | N30: 0,590** | O30: 0,510** | P30: 0,406* | Q30: 0.33237681 | R30: 0,441* | S30: 0,538** | T30: 0.30757342 | U30: 0,554** | V30: 0,778**
B31: Sig. (2-tailed) | C31: 0.012964087 | D31: 0.011149119 | E31: 0.013972348 | F31: 0.0072083685 | G31: 0.0038648915 | H31: 3.2319303e-06 | I31: 7.311953e-06 | J31: 0.00018800962 | K31: 1.6654919e-05 | M31: 0.0078399695 | N31: 0.0003743165 | O31: 0.0028827273 | P31: 0.020961593 | Q31: 0.063078259 | R31: 0.011497916 | S31: 0.0014923439 | T31: 0.08681071 | U31: 0.0010104544 | V31: 1.5718069e-07
B32: N | C32: 32 | D32: 32 | E32: 32 | F32: 32 | G32: 32 | H32: 32 | I32: 32 | J32: 32 | K32: 32 | L32: 32 | M32: 32 | N32: 32 | O32: 32 | P32: 32 | Q32: 32 | R32: 32 | S32: 32 | T32: 32 | U32: 32 | V32: 32
A33: BO11 | B33: Pearson Correlation | C33: 0.20064309 | D33: 0.10183502 | E33: 0.12004128 | F33: 0,412* | G33: 0.27399831 | H33: 0,548** | I33: 0,432* | J33: 0,533** | K33: 0,382* | L33: 0,462** | M33: 1 | N33: 0,429* | O33: 0,487** | P33: 0,401* | Q33: 0,483** | R33: 0,521** | S33: 0,707** | T33: 0,462** | U33: 0,445* | V33: 0,649**
B34: Sig. (2-tailed) | C34: 0.27085505 | D34: 0.57917398 | E34: 0.51284641 | F34: 0.019166181 | G34: 0.12913736 | H34: 0.0011753423 | I34: 0.013577236 | J34: 0.001670024 | K34: 0.031176742 | L34: 0.0078399695 | N34: 0.014216193 | O34: 0.0047158908 | P34: 0.022933642 | Q34: 0.0051175694 | R34: 0.002220856 | S34: 6.1851093e-06 | T34: 0.0078399695 | U34: 0.010660965 | V34: 5.9432711e-05
B35: N | C35: 32 | D35: 32 | E35: 32 | F35: 32 | G35: 32 | H35: 32 | I35: 32 | J35: 32 | K35: 32 | L35: 32 | M35: 32 | N35: 32 | O35: 32 | P35: 32 | Q35: 32 | R35: 32 | S35: 32 | T35: 32 | U35: 32 | V35: 32
A36: BO12 | B36: Pearson Correlation | C36: 0.2997346 | D36: 0.28851905 | E36: 0.25015697 | F36: 0,360* | G36: 0.28699289 | H36: 0,596** | I36: 0,549** | J36: 0,542** | K36: 0,704** | L36: 0,590** | M36: 0,429* | N36: 1 | O36: 0,455** | P36: 0,466** | Q36: 0,373* | R36: 0,464** | S36: 0.25185824 | T36: 0.27866774 | U36: 0.26356015 | V36: 0,646**
B37: Sig. (2-tailed) | C37: 0.095580982 | D37: 0.10927888 | E37: 0.16731866 | F37: 0.043198649 | G37: 0.11125111 | H37: 0.00032229234 | I37: 0.0011525393 | J37: 0.0013455335 | K37: 7.0344919e-06 | L37: 0.0003743165 | M37: 0.014216193 | O37: 0.0089559533 | P37: 0.0072223202 | Q37: 0.035423193 | R37: 0.0074551911 | S37: 0.16435397 | T37: 0.12248159 | U37: 0.14497357 | V37: 6.6010221e-05
B38: N | C38: 32 | D38: 32 | E38: 32 | F38: 32 | G38: 32 | H38: 32 | I38: 32 | J38: 32 | K38: 32 | L38: 32 | M38: 32 | N38: 32 | O38: 32 | P38: 32 | Q38: 32 | R38: 32 | S38: 32 | T38: 32 | U38: 32 | V38: 32
A39: BO13 | B39: Pearson Correlation | C39: 0.19781414 | D39: 0.11952286 | E39: 0.19724795 | F39: 0.34664606 | G39: 0,570** | H39: 0,550** | I39: 0,514** | J39: 0,738** | K39: 0,426* | L39: 0,510** | M39: 0,487** | N39: 0,455** | O39: 1 | P39: 0,510** | Q39: 0,452** | R39: 0,416* | S39: 0,504** | T39: 0.31080491 | U39: 0,629** | V39: 0,694**
B40: Sig. (2-tailed) | C40: 0.27780937 | D40: 0.51468166 | E40: 0.27921496 | F40: 0.05193722 | G40: 0.00065503056 | H40: 0.0011100465 | I40: 0.0026261137 | J40: 1.4312139e-06 | K40: 0.01496785 | L40: 0.0028827273 | M40: 0.0047158908 | N40: 0.0089559533 | P40: 0.0028827273 | Q40: 0.0094559306 | R40: 0.017880985 | S40: 0.003248491 | T40: 0.083380212 | U40: 0.00011553998 | V40: 1.0560624e-05
...

Sheet Kinerja Pegawai
A1: Correlations | W1: Reliability Statistics
C2: KiP1 | D2: KiP2 | E2: KiP3 | F2: KiP4 | G2: KiP5 | H2: KiP6 | I2: KiP7 | J2: KiP8 | K2: KiP9 | L2: KiP10 | M2: KiP11 | N2: KiP12 | O2: KiP13 | P2: KiP | R2: Indikator | S2: Pearson | T2: p-value | U2: Keterangan | W2: Cronbach's Alpha | X2: N of Items | Z2: Cronbach's Alpha | AA2: Keterangan
A3: KiP1 | B3: Pearson Correlation | C3: 1 | D3: 0,706** | E3: 0,738** | F3: 0,485** | G3: 0,619** | H3: 0,578** | I3: -0,429* | J3: 0,409* | K3: 0,573** | L3: 0,392* | M3: 0,395* | N3: 0.32163376 | O3: 0.28365431 | P3: 0,719** | R3: {=INDIRECT("A" & (ROW(R1)*3))} -> KiP1 | S3: {=INDIRECT("P" & (ROW(R1)*3))} -> 0,719** | T3: {=INDIRECT("P" & (ROW(P1)*3+1))} -> 3.5279612e-06 | U3: =IF(T3<0.05,"Valid","Tidak Valid") -> Valid | W3: 0.84423571 | X3: 13 | Z3: =W3 -> 0.84423571 | AA3: =IF(Z3>0.6,"Reliabel","Tidak Reliabel") -> Reliabel
B4: Sig. (2-tailed) | D4: 6.2380222e-06 | E4: 1.4532627e-06 | F4: 0.0049301285 | G4: 0.0001607551 | H4: 0.00053786233 | I4: 0.014323628 | J4: 0.020082641 | K4: 0.00061212729 | L4: 0.026612604 | M4: 0.025375899 | N4: 0.072639812 | O4: 0.11565827 | P4: 3.5279612e-06 | R4: {=INDIRECT("A" & (ROW(R2)*3))} -> KiP2 | S4: {=INDIRECT("P" & (ROW(R2)*3))} -> 0,750** | T4: {=INDIRECT("P" & (ROW(P2)*3+1))} -> 7.5559982e-07 | U4: =IF(T4<0.05,"Valid","Tidak Valid") -> Valid
B5: N | C5: 32 | D5: 32 | E5: 32 | F5: 32 | G5: 32 | H5: 32 | I5: 32 | J5: 32 | K5: 32 | L5: 32 | M5: 32 | N5: 32 | O5: 32 | P5: 32 | R5: {=INDIRECT("A" & (ROW(R3)*3))} -> KiP3 | S5: {=INDIRECT("P" & (ROW(R3)*3))} -> 0,899** | T5: {=INDIRECT("P" & (ROW(P3)*3+1))} -> 2.6584727e-12 | U5: =IF(T5<0.05,"Valid","Tidak Valid") -> Valid
A6: KiP2 | B6: Pearson Correlation | C6: 0,706** | D6: 1 | E6: 0,701** | F6: 0,548** | G6: 0,482** | H6: 0,604** | I6: -0,507** | J6: 0,536** | K6: 0,564** | L6: 0,401* | M6: 0,658** | N6: 0.32254297 | O6: 0.30767708 | P6: 0,750** | R6: {=INDIRECT("A" & (ROW(R4)*3))} -> KiP4 | S6: {=INDIRECT("P" & (ROW(R4)*3))} -> 0,768** | T6: {=INDIRECT("P" & (ROW(P4)*3+1))} -> 2.8822264e-07 | U6: =IF(T6<0.05,"Valid","Tidak Valid") -> Valid
B7: Sig. (2-tailed) | C7: 6.2380222e-06 | E7: 7.7565336e-06 | F7: 0.0011637287 | G7: 0.0052521992 | H7: 0.00025511739 | I7: 0.0030719913 | J7: 0.001581824 | K7: 0.0007776018 | L7: 0.023096835 | M7: 4.2287542e-05 | N7: 0.071789419 | O7: 0.086699013 | P7: 7.5559982e-07 | R7: {=INDIRECT("A" & (ROW(R5)*3))} -> KiP5 | S7: {=INDIRECT("P" & (ROW(R5)*3))} -> 0,695** | T7: {=INDIRECT("P" & (ROW(P5)*3+1))} -> 1.0100805e-05 | U7: =IF(T7<0.05,"Valid","Tidak Valid") -> Valid
B8: N | C8: 32 | D8: 32 | E8: 32 | F8: 32 | G8: 32 | H8: 32 | I8: 32 | J8: 32 | K8: 32 | L8: 32 | M8: 32 | N8: 32 | O8: 32 | P8: 32 | R8: {=INDIRECT("A" & (ROW(R6)*3))} -> KiP6 | S8: {=INDIRECT("P" & (ROW(R6)*3))} -> 0,760** | T8: {=INDIRECT("P" & (ROW(P6)*3+1))} -> 4.5009779e-07 | U8: =IF(T8<0.05,"Valid","Tidak Valid") -> Valid
A9: KiP3 | B9: Pearson Correlation | C9: 0,738** | D9: 0,701** | E9: 1 | F9: 0,741** | G9: 0,541** | H9: 0,721** | I9: -0.31277162 | J9: 0,537** | K9: 0,707** | L9: 0,604** | M9: 0,542** | N9: 0,521** | O9: 0,499** | P9: 0,899** | R9: {=INDIRECT("A" & (ROW(R7)*3))} -> KiP7 | S9: {=INDIRECT("P" & (ROW(R7)*3))} -> -0.26157486 | T9: {=INDIRECT("P" & (ROW(P7)*3+1))} -> 0.14813865 | U9: =IF(T9<0.05,"Valid","Tidak Valid") -> Tidak Valid
B10: Sig. (2-tailed) | C10: 1.4532627e-06 | D10: 7.7565336e-06 | F10: 1.2096558e-06 | G10: 0.0014037498 | H10: 3.2047346e-06 | I10: 0.081343974 | J10: 0.0015458095 | K10: 6.1498024e-06 | L10: 0.00025014965 | M10: 0.0013384107 | N10: 0.0022178971 | O10: 0.003635737 | P10: 2.6584727e-12 | R10: {=INDIRECT("A" & (ROW(R8)*3))} -> KiP8 | S10: {=INDIRECT("P" & (ROW(R8)*3))} -> 0,674** | T10: {=INDIRECT("P" & (ROW(P8)*3+1))} -> 2.3806599e-05 | U10: =IF(T10<0.05,"Valid","Tidak Valid") -> Valid
B11: N | C11: 32 | D11: 32 | E11: 32 | F11: 32 | G11: 32 | H11: 32 | I11: 32 | J11: 32 | K11: 32 | L11: 32 | M11: 32 | N11: 32 | O11: 32 | P11: 32 | R11: {=INDIRECT("A" & (ROW(R9)*3))} -> KiP9 | S11: {=INDIRECT("P" & (ROW(R9)*3))} -> 0,745** | T11: {=INDIRECT("P" & (ROW(P9)*3+1))} -> 1.0222938e-06 | U11: =IF(T11<0.05,"Valid","Tidak Valid") -> Valid
A12: KiP4 | B12: Pearson Correlation | C12: 0,485** | D12: 0,548** | E12: 0,741** | F12: 1 | G12: 0,488** | H12: 0,515** | I12: -0,351* | J12: 0,417* | K12: 0,638** | L12: 0,603** | M12: 0,403* | N12: 0,571** | O12: 0,514** | P12: 0,768** | R12: {=INDIRECT("A" & (ROW(R10)*3))} -> KiP10 | S12: {=INDIRECT("P" & (ROW(R10)*3))} -> 0,696** | T12: {=INDIRECT("P" & (ROW(P10)*3+1))} -> 9.84439e-06 | U12: =IF(T12<0.05,"Valid","Tidak Valid") -> Valid
B13: Sig. (2-tailed) | C13: 0.0049301285 | D13: 0.0011637287 | E13: 1.2096558e-06 | G13: 0.0045861193 | H13: 0.0025467847 | I13: 0.048757895 | J13: 0.017647598 | K13: 8.5581772e-05 | L13: 0.0002609925 | M13: 0.022221853 | N13: 0.00064887644 | O13: 0.0026004238 | P13: 2.8822264e-07 | R13: {=INDIRECT("A" & (ROW(R11)*3))} -> KiP11 | S13: {=INDIRECT("P" & (ROW(R11)*3))} -> 0,674** | T13: {=INDIRECT("P" & (ROW(P11)*3+1))} -> 2.3504801e-05 | U13: =IF(T13<0.05,"Valid","Tidak Valid") -> Valid
B14: N | C14: 32 | D14: 32 | E14: 32 | F14: 32 | G14: 32 | H14: 32 | I14: 32 | J14: 32 | K14: 32 | L14: 32 | M14: 32 | N14: 32 | O14: 32 | P14: 32 | R14: {=INDIRECT("A" & (ROW(R12)*3))} -> KiP12 | S14: {=INDIRECT("P" & (ROW(R12)*3))} -> 0,605** | T14: {=INDIRECT("P" & (ROW(P12)*3+1))} -> 0.0002478304 | U14: =IF(T14<0.05,"Valid","Tidak Valid") -> Valid
A15: KiP5 | B15: Pearson Correlation | C15: 0,619** | D15: 0,482** | E15: 0,541** | F15: 0,488** | G15: 1 | H15: 0,479** | I15: -0.1254363 | J15: 0,423* | K15: 0,418* | L15: 0,495** | M15: 0.332501 | N15: 0.2508726 | O15: 0.24232016 | P15: 0,695** | R15: {=INDIRECT("A" & (ROW(R13)*3))} -> KiP13 | S15: {=INDIRECT("P" & (ROW(R13)*3))} -> 0,625** | T15: {=INDIRECT("P" & (ROW(P13)*3+1))} -> 0.00012945653 | U15: =IF(T15<0.05,"Valid","Tidak Valid") -> Valid
B16: Sig. (2-tailed) | C16: 0.0001607551 | D16: 0.0052521992 | E16: 0.0014037498 | F16: 0.0045861193 | H16: 0.0055519695 | I16: 0.49394154 | J16: 0.015870173 | K16: 0.017295698 | L16: 0.0039582349 | M16: 0.062973812 | N16: 0.16606696 | O16: 0.18146798 | P16: 1.0100805e-05
B17: N | C17: 32 | D17: 32 | E17: 32 | F17: 32 | G17: 32 | H17: 32 | I17: 32 | J17: 32 | K17: 32 | L17: 32 | M17: 32 | N17: 32 | O17: 32 | P17: 32
A18: KiP6 | B18: Pearson Correlation | C18: 0,578** | D18: 0,604** | E18: 0,721** | F18: 0,515** | G18: 0,479** | H18: 1 | I18: -0.28352399 | J18: 0.33712639 | K18: 0,381* | L18: 0,493** | M18: 0,543** | N18: 0.34022879 | O18: 0.32148598 | P18: 0,760**
B19: Sig. (2-tailed) | C19: 0.00053786233 | D19: 0.00025511739 | E19: 3.2047346e-06 | F19: 0.0025467847 | G19: 0.0055519695 | I19: 0.11583291 | J19: 0.059179318 | K19: 0.031377096 | L19: 0.0041505004 | M19: 0.0013284656 | N19: 0.056736775 | O19: 0.072778763 | P19: 4.5009779e-07
B20: N | C20: 32 | D20: 32 | E20: 32 | F20: 32 | G20: 32 | H20: 32 | I20: 32 | J20: 32 | K20: 32 | L20: 32 | M20: 32 | N20: 32 | O20: 32 | P20: 32
A21: KiP7 | B21: Pearson Correlation | C21: -0,429* | D21: -0,507** | E21: -0.31277162 | F21: -0,351* | G21: -0.1254363 | H21: -0.28352399 | I21: 1 | J21: -0.13310348 | K21: -0.229794 | L21: -0,378* | M21: -0.34361649 | N21: -0,375* | O21: -0.31497039 | P21: -0.26157486
B22: Sig. (2-tailed) | C22: 0.014323628 | D22: 0.0030719913 | E22: 0.081343974 | F22: 0.048757895 | G22: 0.49394154 | H22: 0.11583291 | J22: 0.467697 | K22: 0.20579771 | L22: 0.032936306 | M22: 0.054161254 | N22: 0.034448192 | O22: 0.07911304 | P22: 0.14813865
B23: N | C23: 32 | D23: 32 | E23: 32 | F23: 32 | G23: 32 | H23: 32 | I23: 32 | J23: 32 | K23: 32 | L23: 32 | M23: 32 | N23: 32 | O23: 32 | P23: 32
A24: KiP8 | B24: Pearson Correlation | C24: 0,409* | D24: 0,536** | E24: 0,537** | F24: 0,417* | G24: 0,423* | H24: 0.33712639 | I24: -0.13310348 | J24: 1 | K24: 0,780** | L24: 0,369* | M24: 0.34411308 | N24: 0.26620695 | O24: 0,369* | P24: 0,674**
B25: Sig. (2-tailed) | C25: 0.020082641 | D25: 0.001581824 | E25: 0.0015458095 | F25: 0.017647598 | G25: 0.015870173 | H25: 0.059179318 | I25: 0.467697 | K25: 1.4229814e-07 | L25: 0.037720488 | M25: 0.053791621 | N25: 0.14083071 | O25: 0.037720488 | P25: 2.3806599e-05
B26: N | C26: 32 | D26: 32 | E26: 32 | F26: 32 | G26: 32 | H26: 32 | I26: 32 | J26: 32 | K26: 32 | L26: 32 | M26: 32 | N26: 32 | O26: 32 | P26: 32
A27: KiP9 | B27: Pearson Correlation | C27: 0,573** | D27: 0,564** | E27: 0,707** | F27: 0,638** | G27: 0,418* | H27: 0,381* | I27: -0.229794 | J27: 0,780** | K27: 1 | L27: 0.34017804 | M27: 0.2509832 | N27: 0,517** | O27: 0,456** | P27: 0,745**
B28: Sig. (2-tailed) | C28: 0.00061212729 | D28: 0.0007776018 | E28: 6.1498024e-06 | F28: 8.5581772e-05 | G28: 0.017295698 | H28: 0.031377096 | I28: 0.20579771 | J28: 1.4229814e-07 | L28: 0.056776081 | M28: 0.16587412 | N28: 0.002444768 | O28: 0.008718911 | P28: 1.0222938e-06
B29: N | C29: 32 | D29: 32 | E29: 32 | F29: 32 | G29: 32 | H29: 32 | I29: 32 | J29: 32 | K29: 32 | L29: 32 | M29: 32 | N29: 32 | O29: 32 | P29: 32
A30: KiP10 | B30: Pearson Correlation | C30: 0,392* | D30: 0,401* | E30: 0,604** | F30: 0,603** | G30: 0,495** | H30: 0,493** | I30: -0,378* | J30: 0,369* | K30: 0.34017804 | L30: 1 | M30: 0,649** | N30: 0,504** | O30: 0,619** | P30: 0,696**
B31: Sig. (2-tailed) | C31: 0.026612604 | D31: 0.023096835 | E31: 0.00025014965 | F31: 0.0002609925 | G31: 0.0039582349 | H31: 0.0041505004 | I31: 0.032936306 | J31: 0.037720488 | K31: 0.056776081 | M31: 5.7899872e-05 | N31: 0.0032743294 | O31: 0.00015858733 | P31: 9.84439e-06
B32: N | C32: 32 | D32: 32 | E32: 32 | F32: 32 | G32: 32 | H32: 32 | I32: 32 | J32: 32 | K32: 32 | L32: 32 | M32: 32 | N32: 32 | O32: 32 | P32: 32
A33: KiP11 | B33: Pearson Correlation | C33: 0,395* | D33: 0,658** | E33: 0,542** | F33: 0,403* | G33: 0.332501 | H33: 0,543** | I33: -0.34361649 | J33: 0.34411308 | K33: 0.2509832 | L33: 0,649** | M33: 1 | N33: 0,442* | O33: 0,550** | P33: 0,674**
B34: Sig. (2-tailed) | C34: 0.025375899 | D34: 4.2287542e-05 | E34: 0.0013384107 | F34: 0.022221853 | G34: 0.062973812 | H34: 0.0013284656 | I34: 0.054161254 | J34: 0.053791621 | K34: 0.16587412 | L34: 5.7899872e-05 | N34: 0.011357926 | O34: 0.0010983067 | P34: 2.3504801e-05
B35: N | C35: 32 | D35: 32 | E35: 32 | F35: 32 | G35: 32 | H35: 32 | I35: 32 | J35: 32 | K35: 32 | L35: 32 | M35: 32 | N35: 32 | O35: 32 | P35: 32
A36: KiP12 | B36: Pearson Correlation | C36: 0.32163376 | D36: 0.32254297 | E36: 0,521** | F36: 0,571** | G36: 0.2508726 | H36: 0.34022879 | I36: -0,375* | J36: 0.26620695 | K36: 0,517** | L36: 0,504** | M36: 0,442* | N36: 1 | O36: 0,882** | P36: 0,605**
B37: Sig. (2-tailed) | C37: 0.072639812 | D37: 0.071789419 | E37: 0.0022178971 | F37: 0.00064887644 | G37: 0.16606696 | H37: 0.056736775 | I37: 0.034448192 | J37: 0.14083071 | K37: 0.002444768 | L37: 0.0032743294 | M37: 0.011357926 | O37: 2.5843145e-11 | P37: 0.0002478304
B38: N | C38: 32 | D38: 32 | E38: 32 | F38: 32 | G38: 32 | H38: 32 | I38: 32 | J38: 32 | K38: 32 | L38: 32 | M38: 32 | N38: 32 | O38: 32 | P38: 32
A39: KiP13 | B39: Pearson Correlation | C39: 0.28365431 | D39: 0.30767708 | E39: 0,499** | F39: 0,514** | G39: 0.24232016 | H39: 0.32148598 | I39: -0.31497039 | J39: 0,369* | K39: 0,456** | L39: 0,619** | M39: 0,550** | N39: 0,882** | O39: 1 | P39: 0,625**
B40: Sig. (2-tailed) | C40: 0.11565827 | D40: 0.086699013 | E40: 0.003635737 | F40: 0.0026004238 | G40: 0.18146798 | H40: 0.072778763 | I40: 0.07911304 | J40: 0.037720488 | K40: 0.008718911 | L40: 0.00015858733 | M40: 0.0010983067 | N40: 2.5843145e-11 | P40: 0.00012945653
...

Sheet Rangkuman Validitas
A1: Indikator | B1: Pearson | C1: p-value | D1: Keterangan
A2: {='Motivasi Berpretasi'!L3:O9} -> MB1 | B2: 0,661** | C2: 3.8224994e-05 | D2: Valid
A3: MB2 | B3: 0,715** | C3: 4.3223371e-06 | D3: Valid
A4: MB3 | B4: 0,765** | C4: 3.3368586e-07 | D4: Valid
A5: MB4 | B5: 0,717** | C5: 3.9029486e-06 | D5: Valid
A6: MB5 | B6: 0,667** | C6: 3.0240109e-05 | D6: Valid
A7: MB6 | B7: 0,688** | C7: 1.3656131e-05 | D7: Valid
A8: MB7 | B8: 0,742** | C8: 1.1784213e-06 | D8: Valid
A9: {='Komitmen Pegawai'!P3:S13} -> KP1 | B9: 0,541** | C9: 0.0013998429 | D9: Valid
A10: KP2 | B10: 0,685** | C10: 1.5511887e-05 | D10: Valid
A11: KP3 | B11: 0,797** | C11: 4.8090071e-08 | D11: Valid
A12: KP4 | B12: 0,726** | C12: 2.5391012e-06 | D12: Valid
A13: KP5 | B13: 0,629** | C13: 0.00011687786 | D13: Valid
A14: KP6 | B14: 0,785** | C14: 1.0484727e-07 | D14: Valid
A15: KP7 | B15: -0.17435189 | C15: 0.33989129 | D15: Tidak Valid
A16: KP8 | B16: 0.035026753 | C16: 0.84906138 | D16: Tidak Valid
A17: KP9 | B17: 0,456** | C17: 0.0087618619 | D17: Valid
A18: KP10 | B18: 0,644** | C18: 6.9215071e-05 | D18: Valid
A19: KP11 | B19: 0,455** | C19: 0.0089262249 | D19: Valid
A20: {='Budaya Organisasi'!X3:AA21} -> BO1 | B20: 0,500** | C20: 0.0035480629 | D20: Valid
A21: BO2 | B21: 0,371* | C21: 0.036744703 | D21: Valid
A22: BO3 | B22: 0,441* | C22: 0.011500942 | D22: Valid
A23: BO4 | B23: 0,610** | C23: 0.00021101342 | D23: Valid
A24: BO5 | B24: 0,737** | C24: 1.4958628e-06 | D24: Valid
A25: BO6 | B25: 0,830** | C25: 4.1069043e-09 | D25: Valid
A26: BO7 | B26: 0,848** | C26: 9.2674778e-10 | D26: Valid
A27: BO8 | B27: 0,817** | C27: 1.1804168e-08 | D27: Valid
A28: BO9 | B28: 0,742** | C28: 1.1676842e-06 | D28: Valid
A29: BO10 | B29: 0,778** | C29: 1.5718069e-07 | D29: Valid
A30: BO11 | B30: 0,649** | C30: 5.9432711e-05 | D30: Valid
A31: BO12 | B31: 0,646** | C31: 6.6010221e-05 | D31: Valid
A32: BO13 | B32: 0,694** | C32: 1.0560624e-05 | D32: Valid
... A38: BO19 | B38: 0,745** | C38: 1.0085767e-06 | D38: Valid
A39: {='Kinerja Pegawai'!R3:U15} -> KiP1 | B39: 0,719** | C39: 3.5279612e-06 | D39: Valid
A40: KiP2 | B40: 0,750** | C40: 7.5559982e-07 | D40: Valid
A41: KiP3 | B41: 0,899** | C41: 2.6584727e-12 | D41: Valid
A42: KiP4 | B42: 0,768** | C42: 2.8822264e-07 | D42: Valid
A43: KiP5 | B43: 0,695** | C43: 1.0100805e-05 | D43: Valid
A44: KiP6 | B44: 0,760** | C44: 4.5009779e-07 | D44: Valid
A45: KiP7 | B45: -0.26157486 | C45: 0.14813865 | D45: Tidak Valid
...

Sheet Rangkuman Reliabilitas
A1: Variabel | B1: Cronbach's Alpha | C1: Keterangan
A2: MB | B2: {='Motivasi Berpretasi'!T3:U3} -> 0.82657767 | C2: Reliabel
A3: KP | B3: {='Komitmen Pegawai'!X3:Y3} -> 0.55321195 | C3: Tidak Reliabel
A4: BO | B4: {='Budaya Organisasi'!AF3:AG3} -> 0.9372805 | C4: Reliabel
A5: KiP | B5: {='Kinerja Pegawai'!Z3:AA3} -> 0.84423571 | C5: Reliabel
